#VRML_SIM R2025a utf8

EXTERNPROTO "https://raw.githubusercontent.com/cyberbotics/webots/released/projects/objects/floors/protos/RectangleArena.proto"

WorldInfo {
  info [
    "Snake Robot with Rolling Locomotion"
    "12-joint snake: H-V H-V H-V H-V H-V H-V arrangement"
    "Controller: snake_controller"
  ]
  title "Snake Robot - Rolling Locomotion"
  basicTimeStep 16
  contactProperties [
    ContactProperties {
      material1 "snake_body"
      coulombFriction [
        0.8
      ]
      softCFM 0.001
      bounce 0.1
    }
  ]
}

Viewpoint {
  orientation -0.3826834323650898 0.0 0.9238795325112867 1.2
  position 0.0 1.2 0.8
  follow "snake_robot"
  followSmoothness 0.5
}

Background {
  skyColor [
    0.15 0.15 0.2
  ]
  groundColor [
    0.3 0.3 0.3
  ]
}

DirectionalLight {
  ambientIntensity 0.4
  direction -0.5 -1 -0.3
  intensity 1.2
  castShadows TRUE
}

RectangleArena {
  translation 0 0 0
  floorSize 4 4
  floorTileSize 0.5 0.5
  floorAppearance PBRAppearance {
    baseColor 0.3 0.35 0.3
    roughness 0.9
    metalness 0.0
  }
  wallHeight 0.1
}

Robot {
  name "snake_robot"
  translation 0 0.05 0
  rotation 0 1 0 0
  controller "snake_controller"
  supervisor FALSE
  children [
    # ── SEGMENT 0 (HEAD / root) ──────────────────────────────────────────
    Shape {
      appearance PBRAppearance {
        baseColor 0.1 0.7 0.3
        roughness 0.4
        metalness 0.1
      }
      geometry Cylinder {
        radius 0.03
        height 0.12
      }
    }

    # ── JOINT 0 : Horizontal (axis 0 1 0) ───────────────────────────────
    HingeJoint {
      jointParameters HingeJointParameters {
        axis 0 1 0
        anchor 0 0 0.06
        minStop -1.5708
        maxStop 1.5708
        dampingConstant 0.1
        staticFriction 0.01
      }
      device [
        RotationalMotor {
          name "motor_H_0"
          maxVelocity 10.0
          maxTorque 10.0
          minPosition -1.5708
          maxPosition 1.5708
        }
        PositionSensor {
          name "sensor_H_0"
        }
      ]
      endPoint Solid {
        name "segment_1"
        translation 0 0 0.12
        children [
          Shape {
            appearance PBRAppearance {
              baseColor 0.1 0.65 0.35
              roughness 0.4
              metalness 0.1
            }
            geometry Cylinder {
              radius 0.03
              height 0.12
            }
          }

          # ── JOINT 1 : Vertical (axis 1 0 0) ─────────────────────────
          HingeJoint {
            jointParameters HingeJointParameters {
              axis 1 0 0
              anchor 0 0 0.06
              minStop -1.5708
              maxStop 1.5708
              dampingConstant 0.1
              staticFriction 0.01
            }
            device [
              RotationalMotor {
                name "motor_V_1"
                maxVelocity 10.0
                maxTorque 10.0
                minPosition -1.5708
                maxPosition 1.5708
              }
              PositionSensor {
                name "sensor_V_1"
              }
            ]
            endPoint Solid {
              name "segment_2"
              translation 0 0 0.12
              children [
                Shape {
                  appearance PBRAppearance {
                    baseColor 0.1 0.60 0.40
                    roughness 0.4
                    metalness 0.1
                  }
                  geometry Cylinder {
                    radius 0.03
                    height 0.12
                  }
                }

                # ── JOINT 2 : Horizontal ─────────────────────────────
                HingeJoint {
                  jointParameters HingeJointParameters {
                    axis 0 1 0
                    anchor 0 0 0.06
                    minStop -1.5708
                    maxStop 1.5708
                    dampingConstant 0.1
                    staticFriction 0.01
                  }
                  device [
                    RotationalMotor {
                      name "motor_H_2"
                      maxVelocity 10.0
                      maxTorque 10.0
                      minPosition -1.5708
                      maxPosition 1.5708
                    }
                    PositionSensor {
                      name "sensor_H_2"
                    }
                  ]
                  endPoint Solid {
                    name "segment_3"
                    translation 0 0 0.12
                    children [
                      Shape {
                        appearance PBRAppearance {
                          baseColor 0.15 0.55 0.45
                          roughness 0.4
                          metalness 0.1
                        }
                        geometry Cylinder {
                          radius 0.03
                          height 0.12
                        }
                      }

                      # ── JOINT 3 : Vertical ───────────────────────
                      HingeJoint {
                        jointParameters HingeJointParameters {
                          axis 1 0 0
                          anchor 0 0 0.06
                          minStop -1.5708
                          maxStop 1.5708
                          dampingConstant 0.1
                          staticFriction 0.01
                        }
                        device [
                          RotationalMotor {
                            name "motor_V_3"
                            maxVelocity 10.0
                            maxTorque 10.0
                            minPosition -1.5708
                            maxPosition 1.5708
                          }
                          PositionSensor {
                            name "sensor_V_3"
                          }
                        ]
                        endPoint Solid {
                          name "segment_4"
                          translation 0 0 0.12
                          children [
                            Shape {
                              appearance PBRAppearance {
                                baseColor 0.15 0.50 0.50
                                roughness 0.4
                                metalness 0.1
                              }
                              geometry Cylinder {
                                radius 0.03
                                height 0.12
                              }
                            }

                            # ── JOINT 4 : Horizontal ─────────────
                            HingeJoint {
                              jointParameters HingeJointParameters {
                                axis 0 1 0
                                anchor 0 0 0.06
                                minStop -1.5708
                                maxStop 1.5708
                                dampingConstant 0.1
                                staticFriction 0.01
                              }
                              device [
                                RotationalMotor {
                                  name "motor_H_4"
                                  maxVelocity 10.0
                                  maxTorque 10.0
                                  minPosition -1.5708
                                  maxPosition 1.5708
                                }
                                PositionSensor {
                                  name "sensor_H_4"
                                }
                              ]
                              endPoint Solid {
                                name "segment_5"
                                translation 0 0 0.12
                                children [
                                  Shape {
                                    appearance PBRAppearance {
                                      baseColor 0.2 0.45 0.55
                                      roughness 0.4
                                      metalness 0.1
                                    }
                                    geometry Cylinder {
                                      radius 0.03
                                      height 0.12
                                    }
                                  }

                                  # ── JOINT 5 : Vertical ───────
                                  HingeJoint {
                                    jointParameters HingeJointParameters {
                                      axis 1 0 0
                                      anchor 0 0 0.06
                                      minStop -1.5708
                                      maxStop 1.5708
                                      dampingConstant 0.1
                                      staticFriction 0.01
                                    }
                                    device [
                                      RotationalMotor {
                                        name "motor_V_5"
                                        maxVelocity 10.0
                                        maxTorque 10.0
                                        minPosition -1.5708
                                        maxPosition 1.5708
                                      }
                                      PositionSensor {
                                        name "sensor_V_5"
                                      }
                                    ]
                                    endPoint Solid {
                                      name "segment_6"
                                      translation 0 0 0.12
                                      children [
                                        Shape {
                                          appearance PBRAppearance {
                                            baseColor 0.2 0.40 0.60
                                            roughness 0.4
                                            metalness 0.1
                                          }
                                          geometry Cylinder {
                                            radius 0.03
                                            height 0.12
                                          }
                                        }

                                        # ── JOINT 6 : Horizontal ─
                                        HingeJoint {
                                          jointParameters HingeJointParameters {
                                            axis 0 1 0
                                            anchor 0 0 0.06
                                            minStop -1.5708
                                            maxStop 1.5708
                                            dampingConstant 0.1
                                            staticFriction 0.01
                                          }
                                          device [
                                            RotationalMotor {
                                              name "motor_H_6"
                                              maxVelocity 10.0
                                              maxTorque 10.0
                                              minPosition -1.5708
                                              maxPosition 1.5708
                                            }
                                            PositionSensor {
                                              name "sensor_H_6"
                                            }
                                          ]
                                          endPoint Solid {
                                            name "segment_7"
                                            translation 0 0 0.12
                                            children [
                                              Shape {
                                                appearance PBRAppearance {
                                                  baseColor 0.25 0.35 0.65
                                                  roughness 0.4
                                                  metalness 0.1
                                                }
                                                geometry Cylinder {
                                                  radius 0.03
                                                  height 0.12
                                                }
                                              }

                                              # ── JOINT 7 : Vertical ─
                                              HingeJoint {
                                                jointParameters HingeJointParameters {
                                                  axis 1 0 0
                                                  anchor 0 0 0.06
                                                  minStop -1.5708
                                                  maxStop 1.5708
                                                  dampingConstant 0.1
                                                  staticFriction 0.01
                                                }
                                                device [
                                                  RotationalMotor {
                                                    name "motor_V_7"
                                                    maxVelocity 10.0
                                                    maxTorque 10.0
                                                    minPosition -1.5708
                                                    maxPosition 1.5708
                                                  }
                                                  PositionSensor {
                                                    name "sensor_V_7"
                                                  }
                                                ]
                                                endPoint Solid {
                                                  name "segment_8"
                                                  translation 0 0 0.12
                                                  children [
                                                    Shape {
                                                      appearance PBRAppearance {
                                                        baseColor 0.25 0.30 0.70
                                                        roughness 0.4
                                                        metalness 0.1
                                                      }
                                                      geometry Cylinder {
                                                        radius 0.03
                                                        height 0.12
                                                      }
                                                    }

                                                    # ── JOINT 8 : Horizontal ─
                                                    HingeJoint {
                                                      jointParameters HingeJointParameters {
                                                        axis 0 1 0
                                                        anchor 0 0 0.06
                                                        minStop -1.5708
                                                        maxStop 1.5708
                                                        dampingConstant 0.1
                                                        staticFriction 0.01
                                                      }
                                                      device [
                                                        RotationalMotor {
                                                          name "motor_H_8"
                                                          maxVelocity 10.0
                                                          maxTorque 10.0
                                                          minPosition -1.5708
                                                          maxPosition 1.5708
                                                        }
                                                        PositionSensor {
                                                          name "sensor_H_8"
                                                        }
                                                      ]
                                                      endPoint Solid {
                                                        name "segment_9"
                                                        translation 0 0 0.12
                                                        children [
                                                          Shape {
                                                            appearance PBRAppearance {
                                                              baseColor 0.30 0.25 0.72
                                                              roughness 0.4
                                                              metalness 0.1
                                                            }
                                                            geometry Cylinder {
                                                              radius 0.03
                                                              height 0.12
                                                            }
                                                          }

                                                          # ── JOINT 9 : Vertical ─
                                                          HingeJoint {
                                                            jointParameters HingeJointParameters {
                                                              axis 1 0 0
                                                              anchor 0 0 0.06
                                                              minStop -1.5708
                                                              maxStop 1.5708
                                                              dampingConstant 0.1
                                                              staticFriction 0.01
                                                            }
                                                            device [
                                                              RotationalMotor {
                                                                name "motor_V_9"
                                                                maxVelocity 10.0
                                                                maxTorque 10.0
                                                                minPosition -1.5708
                                                                maxPosition 1.5708
                                                              }
                                                              PositionSensor {
                                                                name "sensor_V_9"
                                                              }
                                                            ]
                                                            endPoint Solid {
                                                              name "segment_10"
                                                              translation 0 0 0.12
                                                              children [
                                                                Shape {
                                                                  appearance PBRAppearance {
                                                                    baseColor 0.35 0.20 0.70
                                                                    roughness 0.4
                                                                    metalness 0.1
                                                                  }
                                                                  geometry Cylinder {
                                                                    radius 0.03
                                                                    height 0.12
                                                                  }
                                                                }

                                                                # ── JOINT 10 : Horizontal ─
                                                                HingeJoint {
                                                                  jointParameters HingeJointParameters {
                                                                    axis 0 1 0
                                                                    anchor 0 0 0.06
                                                                    minStop -1.5708
                                                                    maxStop 1.5708
                                                                    dampingConstant 0.1
                                                                    staticFriction 0.01
                                                                  }
                                                                  device [
                                                                    RotationalMotor {
                                                                      name "motor_H_10"
                                                                      maxVelocity 10.0
                                                                      maxTorque 10.0
                                                                      minPosition -1.5708
                                                                      maxPosition 1.5708
                                                                    }
                                                                    PositionSensor {
                                                                      name "sensor_H_10"
                                                                    }
                                                                  ]
                                                                  endPoint Solid {
                                                                    name "segment_11"
                                                                    translation 0 0 0.12
                                                                    children [
                                                                      Shape {
                                                                        appearance PBRAppearance {
                                                                          baseColor 0.40 0.15 0.65
                                                                          roughness 0.4
                                                                          metalness 0.1
                                                                        }
                                                                        geometry Cylinder {
                                                                          radius 0.03
                                                                          height 0.12
                                                                        }
                                                                      }

                                                                      # ── JOINT 11 : Vertical (TAIL) ─
                                                                      HingeJoint {
                                                                        jointParameters HingeJointParameters {
                                                                          axis 1 0 0
                                                                          anchor 0 0 0.06
                                                                          minStop -1.5708
                                                                          maxStop 1.5708
                                                                          dampingConstant 0.1
                                                                          staticFriction 0.01
                                                                        }
                                                                        device [
                                                                          RotationalMotor {
                                                                            name "motor_V_11"
                                                                            maxVelocity 10.0
                                                                            maxTorque 10.0
                                                                            minPosition -1.5708
                                                                            maxPosition 1.5708
                                                                          }
                                                                          PositionSensor {
                                                                            name "sensor_V_11"
                                                                          }
                                                                        ]
                                                                        endPoint Solid {
                                                                          name "segment_12_tail"
                                                                          translation 0 0 0.12
                                                                          children [
                                                                            Shape {
                                                                              appearance PBRAppearance {
                                                                                baseColor 0.45 0.10 0.60
                                                                                roughness 0.4
                                                                                metalness 0.1
                                                                              }
                                                                              geometry Cylinder {
                                                                                radius 0.025
                                                                                height 0.10
                                                                              }
                                                                            }
                                                                          ]
                                                                          boundingObject Cylinder {
                                                                            radius 0.025
                                                                            height 0.10
                                                                          }
                                                                          physics Physics {
                                                                            density -1
                                                                            mass 0.05
                                                                            centerOfMass [ 0 0 0 ]
                                                                            inertiaMatrix [
                                                                              1e-05 1e-05 1e-05
                                                                              0 0 0
                                                                            ]
                                                                          }
                                                                          contactMaterial "snake_body"
                                                                        }
                                                                      }
                                                                    ]
                                                                    boundingObject Cylinder {
                                                                      radius 0.03
                                                                      height 0.12
                                                                    }
                                                                    physics Physics {
                                                                      density -1
                                                                      mass 0.08
                                                                      centerOfMass [ 0 0 0 ]
                                                                      inertiaMatrix [
                                                                        1e-05 1e-05 1e-05
                                                                        0 0 0
                                                                      ]
                                                                    }
                                                                    contactMaterial "snake_body"
                                                                  }
                                                                }
                                                              ]
                                                              boundingObject Cylinder {
                                                                radius 0.03
                                                                height 0.12
                                                              }
                                                              physics Physics {
                                                                density -1
                                                                mass 0.08
                                                                centerOfMass [ 0 0 0 ]
                                                                inertiaMatrix [
                                                                  1e-05 1e-05 1e-05
                                                                  0 0 0
                                                                ]
                                                              }
                                                              contactMaterial "snake_body"
                                                            }
                                                          }
                                                        ]
                                                        boundingObject Cylinder {
                                                          radius 0.03
                                                          height 0.12
                                                        }
                                                        physics Physics {
                                                          density -1
                                                          mass 0.08
                                                          centerOfMass [ 0 0 0 ]
                                                          inertiaMatrix [
                                                            1e-05 1e-05 1e-05
                                                            0 0 0
                                                          ]
                                                        }
                                                        contactMaterial "snake_body"
                                                      }
                                                    }
                                                  ]
                                                  boundingObject Cylinder {
                                                    radius 0.03
                                                    height 0.12
                                                  }
                                                  physics Physics {
                                                    density -1
                                                    mass 0.08
                                                    centerOfMass [ 0 0 0 ]
                                                    inertiaMatrix [
                                                      1e-05 1e-05 1e-05
                                                      0 0 0
                                                    ]
                                                  }
                                                  contactMaterial "snake_body"
                                                }
                                              }
                                            ]
                                            boundingObject Cylinder {
                                              radius 0.03
                                              height 0.12
                                            }
                                            physics Physics {
                                              density -1
                                              mass 0.08
                                              centerOfMass [ 0 0 0 ]
                                              inertiaMatrix [
                                                1e-05 1e-05 1e-05
                                                0 0 0
                                              ]
                                            }
                                            contactMaterial "snake_body"
                                          }
                                        }
                                      ]
                                      boundingObject Cylinder {
                                        radius 0.03
                                        height 0.12
                                      }
                                      physics Physics {
                                        density -1
                                        mass 0.08
                                        centerOfMass [ 0 0 0 ]
                                        inertiaMatrix [
                                          1e-05 1e-05 1e-05
                                          0 0 0
                                        ]
                                      }
                                      contactMaterial "snake_body"
                                    }
                                  }
                                ]
                                boundingObject Cylinder {
                                  radius 0.03
                                  height 0.12
                                }
                                physics Physics {
                                  density -1
                                  mass 0.08
                                  centerOfMass [ 0 0 0 ]
                                  inertiaMatrix [
                                    1e-05 1e-05 1e-05
                                    0 0 0
                                  ]
                                }
                                contactMaterial "snake_body"
                              }
                            }
                          ]
                          boundingObject Cylinder {
                            radius 0.03
                            height 0.12
                          }
                          physics Physics {
                            density -1
                            mass 0.08
                            centerOfMass [ 0 0 0 ]
                            inertiaMatrix [
                              1e-05 1e-05 1e-05
                              0 0 0
                            ]
                          }
                          contactMaterial "snake_body"
                        }
                      }
                    ]
                    boundingObject Cylinder {
                      radius 0.03
                      height 0.12
                    }
                    physics Physics {
                      density -1
                      mass 0.08
                      centerOfMass [ 0 0 0 ]
                      inertiaMatrix [
                        1e-05 1e-05 1e-05
                        0 0 0
                      ]
                    }
                    contactMaterial "snake_body"
                  }
                }
              ]
              boundingObject Cylinder {
                radius 0.03
                height 0.12
              }
              physics Physics {
                density -1
                mass 0.08
                centerOfMass [ 0 0 0 ]
                inertiaMatrix [
                  1e-05 1e-05 1e-05
                  0 0 0
                ]
              }
              contactMaterial "snake_body"
            }
          }
        ]
        boundingObject Cylinder {
          radius 0.03
          height 0.12
        }
        physics Physics {
          density -1
          mass 0.08
          centerOfMass [ 0 0 0 ]
          inertiaMatrix [
            1e-05 1e-05 1e-05
            0 0 0
          ]
        }
        contactMaterial "snake_body"
      }
    }
  ]
  boundingObject Cylinder {
    radius 0.03
    height 0.12
  }
  physics Physics {
    density -1
    mass 0.10
    centerOfMass [ 0 0 0 ]
    inertiaMatrix [
      1e-05 1e-05 1e-05
      0 0 0
    ]
  }
  contactMaterial "snake_body"
}
